# Handling errors generated by tests (Python)

Groktest doesn't apply special handling for errors in the way that
`doctest` does. If an error occurs, its traceback is used as outout.

    >>> def boom():
    ...     import sys, os
    ...     sys.path.append(os.path.dirname(__file__))
    ...     import util
    ...     util.boom()

    >>> boom()  # +wildcard +error-detail +diff
    Traceback (most recent call last):
      File ".../examples/errors.md", line 12, in <module>
        boom()  # +wildcard +error-detail +diff
      File ".../examples/errors.md", line 10, in boom
            util.boom()
      File ".../examples/util.py", line 2, in boom
        return 1 / 0
    ZeroDivisionError: division by zero

    >>> boom()
    Traceback (most recent call last):
    ZeroDivisionError: division by zero


Problems:

3 - No way in Groktest to ignore error detail (traceback) without wildcard or parse
    matching

    Expected behavior:

    >> boom()  # -error-detail
    Traceback (most recent call last):
    ZeroDivisionError: division by zero
